Workbook
Name Z_857CB3B9_618A_49FD_8D38_75EE2A4021B4_.wvu.PrintArea: 'C01'!$B$1:$D$302
Name Z_857CB3B9_618A_49FD_8D38_75EE2A4021B4_.wvu.PrintArea: 'C010'!$B$1:$D$302
Name Z_857CB3B9_618A_49FD_8D38_75EE2A4021B4_.wvu.PrintArea: 'C011'!$B$1:$D$302
Name Z_857CB3B9_618A_49FD_8D38_75EE2A4021B4_.wvu.PrintArea: 'C012'!$B$1:$D$302
Name Z_857CB3B9_618A_49FD_8D38_75EE2A4021B4_.wvu.PrintArea: 'C013'!$B$1:$D$302
Name Z_857CB3B9_618A_49FD_8D38_75EE2A4021B4_.wvu.PrintArea: 'C014'!$B$1:$D$302
Name Z_857CB3B9_618A_49FD_8D38_75EE2A4021B4_.wvu.PrintArea: 'C015'!$B$1:$D$302
Name Z_857CB3B9_618A_49FD_8D38_75EE2A4021B4_.wvu.PrintArea: 'C016'!$B$1:$D$302
Name Z_857CB3B9_618A_49FD_8D38_75EE2A4021B4_.wvu.PrintArea: 'C017'!$B$1:$D$302
Name Z_857CB3B9_618A_49FD_8D38_75EE2A4021B4_.wvu.PrintArea: 'C018'!$B$1:$D$302
Name Z_857CB3B9_618A_49FD_8D38_75EE2A4021B4_.wvu.PrintArea: 'C019'!$B$1:$D$302
Name Z_857CB3B9_618A_49FD_8D38_75EE2A4021B4_.wvu.PrintArea: 'C02'!$B$1:$D$302
Name Z_857CB3B9_618A_49FD_8D38_75EE2A4021B4_.wvu.PrintArea: 'C020'!$B$1:$D$302
Name Z_857CB3B9_618A_49FD_8D38_75EE2A4021B4_.wvu.PrintArea: 'C021'!$B$1:$D$302
Name Z_857CB3B9_618A_49FD_8D38_75EE2A4021B4_.wvu.PrintArea: 'C022'!$B$1:$D$302
Name Z_857CB3B9_618A_49FD_8D38_75EE2A4021B4_.wvu.PrintArea: 'C023'!$B$1:$D$302
Name Z_857CB3B9_618A_49FD_8D38_75EE2A4021B4_.wvu.PrintArea: 'C024'!$B$1:$D$302
Name Z_857CB3B9_618A_49FD_8D38_75EE2A4021B4_.wvu.PrintArea: 'C025'!$B$1:$D$302
Name Z_857CB3B9_618A_49FD_8D38_75EE2A4021B4_.wvu.PrintArea: 'C026'!$B$1:$D$302
Name Z_857CB3B9_618A_49FD_8D38_75EE2A4021B4_.wvu.PrintArea: 'C027'!$B$1:$D$302
Name Z_857CB3B9_618A_49FD_8D38_75EE2A4021B4_.wvu.PrintArea: 'C028'!$B$1:$D$302
Name Z_857CB3B9_618A_49FD_8D38_75EE2A4021B4_.wvu.PrintArea: 'C029'!$B$1:$D$302
Name Z_857CB3B9_618A_49FD_8D38_75EE2A4021B4_.wvu.PrintArea: 'C03'!$B$1:$D$302
Name Z_857CB3B9_618A_49FD_8D38_75EE2A4021B4_.wvu.PrintArea: 'C030'!$B$1:$D$302
Name Z_857CB3B9_618A_49FD_8D38_75EE2A4021B4_.wvu.PrintArea: 'C031'!$B$1:$D$302
Name Z_857CB3B9_618A_49FD_8D38_75EE2A4021B4_.wvu.PrintArea: 'C032'!$B$1:$D$302
Name Z_857CB3B9_618A_49FD_8D38_75EE2A4021B4_.wvu.PrintArea: 'C033'!$B$1:$D$302
Name Z_857CB3B9_618A_49FD_8D38_75EE2A4021B4_.wvu.PrintArea: 'C034'!$B$1:$D$302
Name Z_857CB3B9_618A_49FD_8D38_75EE2A4021B4_.wvu.PrintArea: 'C035'!$B$1:$D$302
Name Z_857CB3B9_618A_49FD_8D38_75EE2A4021B4_.wvu.PrintArea: 'C036'!$B$1:$D$302
Name Z_857CB3B9_618A_49FD_8D38_75EE2A4021B4_.wvu.PrintArea: 'C037'!$B$1:$D$302
Name Z_857CB3B9_618A_49FD_8D38_75EE2A4021B4_.wvu.PrintArea: 'C038'!$B$1:$D$302
Name Z_857CB3B9_618A_49FD_8D38_75EE2A4021B4_.wvu.PrintArea: 'C039'!$B$1:$D$302
Name Z_857CB3B9_618A_49FD_8D38_75EE2A4021B4_.wvu.PrintArea: 'C04'!$B$1:$D$302
Name Z_857CB3B9_618A_49FD_8D38_75EE2A4021B4_.wvu.PrintArea: 'C040'!$B$1:$D$302
Name Z_857CB3B9_618A_49FD_8D38_75EE2A4021B4_.wvu.PrintArea: 'C041'!$B$1:$D$302
Name Z_857CB3B9_618A_49FD_8D38_75EE2A4021B4_.wvu.PrintArea: 'C042'!$B$1:$D$302
Name Z_857CB3B9_618A_49FD_8D38_75EE2A4021B4_.wvu.PrintArea: 'C043'!$B$1:$D$302
Name Z_857CB3B9_618A_49FD_8D38_75EE2A4021B4_.wvu.PrintArea: 'C05'!$B$1:$D$302
Name Z_857CB3B9_618A_49FD_8D38_75EE2A4021B4_.wvu.PrintArea: 'C06'!$B$1:$D$302
Name Z_857CB3B9_618A_49FD_8D38_75EE2A4021B4_.wvu.PrintArea: 'C07'!$B$1:$D$302
Name Z_857CB3B9_618A_49FD_8D38_75EE2A4021B4_.wvu.PrintArea: 'C08'!$B$1:$D$302
Name Z_857CB3B9_618A_49FD_8D38_75EE2A4021B4_.wvu.PrintArea: 'C09'!$B$1:$D$302
Name Z_857CB3B9_618A_49FD_8D38_75EE2A4021B4_.wvu.PrintArea: INSTRUCCIONES!$B$5:$O$25
Name Z_857CB3B9_618A_49FD_8D38_75EE2A4021B4_.wvu.PrintArea: PORTADA!$B$2:$K$41
Name Z_857CB3B9_618A_49FD_8D38_75EE2A4021B4_.wvu.PrintArea: PRESENTACIÓN!$B$4:$O$53
Name Z_857CB3B9_618A_49FD_8D38_75EE2A4021B4_.wvu.PrintArea: RESUMEN!$A$1:$G$22

Sheet PORTADA
B2: |
B12: Formato electrónico FESE (Formato Estadístico de los Servicios de Emergencia)para el reporte estadístico mensual del número de llamadas generadas en el Servicio de Atención de Llamadas de Emergencia
K38: Centro Nacional de Información
K39: Secretariado Ejecutivo del Sistema Nacional de Seguridad Pública
K41: 2022

Sheet PRESENTACIÓN
B8: CENTRO NACIONAL DE INFORMACIÓN
B9: PRESENTACIÓN
B10: REPORTE ESTADÍSTICO MENSUAL DEL NÚMERO DE LLAMADAS GENERADAS EN EL SERVICIO DE ATENCIÓN DE LLAMADAS DE EMERGENCIA 911
B11: (FORMATO ELECTRÓNICO FESE)
B13: OBJETIVO
B14: Integrar, análisar y explotar la información generada de los tipos de incidentes de los Centros de Atención de Llamadas de Emergencia 066 que operan a nivel nacional.
B18: Ley General del Sistema Nacional de Seguridad Pública
B19: Artículo 111.- La Federación, los Estados, el Distrito Federal y los Municipios, realizarán los trabajos para lograr la compatibilidad de los servicios de telecomunicaciones de su Red Local correspondiente, con las bases de datos criminalísticos y de personal del Sistema, previstas en la presente Ley. El servicio de llamadas de emergencia y el servicio de denuncia anónima operarán con un número único de atención a la ciudadanía. El Secretario Ejecutivo adoptará las medidas necesarias para la homologación de los servicios.”
B25: Acuerdo Nacional por la Seguridad, la Justicia y la Legalidad
B26: 10/XXXVII/14. El Consejo Nacional de Seguridad Pública aprueba la consolidación de un servicio homologado para la atención de llamadas de emergencia en todo el país, que opere de manera estandarizada a nivel nacional, reduzca los tiempos de atención y mejore la calidad del servicio prestado a la ciudadanía. Para ello, se instruye al Secretariado Ejecutivo del Sistema Nacional de Seguridad Pública a realizar un diagnóstico a nivel nacional y, con base en éste, diseñar el programa que definirá las acciones y metas que las autoridades de los tres órdenes de gobierno deberán de cumplir a fin de ejecutar dicho acuerdo, así como las etapas y tiempos para la homologación del servicio y la desaparición progresiva de los números de atención de emergencia actuales. Acuerdo 12/XXXVIII/15. Catálogo Nacional de Incidentes de Emergencia e integración de Base Nacional. En el marco del Acuerdo 10/XXXVII/14, el Consejo Nacional de Seguridad Pública aprueba el Catálogo Nacional de Incidentes de Emergencia y su implementación obligatoria en los Servicios de Atención de Llamadas de Emergencia a nivel nacional, con base en los términos y plazos que determine el Secretariado Ejecutivo del Sistema Nacional de Seguridad Pública. Asimismo, se instruye a los responsables de los Servicios de Atención de Llamadas de Emergencia, a que proporcionen al Secretariado Ejecutivo del Sistema Nacional de Seguridad Pública, información periódica sobre sus incidentes, con base en dicho Catálogo.
B40: Acuerdos aprobados por el Consejo Nacional de Seguridad Pública en su Trigésima Primera Sesión.
B41: Acuerdo 03/XXXVIII/15. Programas con Prioridad Nacional. El Consejo Nacional de Seguridad Pública aprueba “Los Ejes Estratégicos del Sistema Nacional de Seguridad Pública y su estructura, así como los Programas con Prioridad Nacional para alcanzarlos, vinculados al ejercicio del fondo, subsidios y demás recursos de carácter federal que se otorguen a las Entidades Federativas, los Municipios y Demarcaciones Territoriales del Distrito Federal, en materia de seguridad pública”.
... B53: Homologar la información sobre incidencia delictiva que generan los centros de atención de llamadas de emergencia, así como generar una base de datos nacional con información estadística.

Sheet INSTRUCCIONES
B8: CENTRO NACIONAL DE INFORMACIÓN
B9: PRESENTACIÓN
B10: REPORTE ESTADÍSTICO MENSUAL DEL NÚMERO DE LLAMADAS GENERADAS EN EL SERVICIO DE ATENCIÓN DE LLAMADAS DE EMERGENCIA 066
B11: (FORMATO ELECTRÓNICO FESE)
B13: INSTRUCTIVO
B14: REPORTE ESTADÍSTICO DEL NÚMERO DE LLAMADAS GENERADAS EN LOS SERVICIOS DE ATENCIÓN DE LLAMADAS DE EMERGENCIA 911
C15: Se deberá enviar en los 10 primeros días de cada mes
C16: La información de la estadística generada en el Centro de Atención de Llamadas de Emergencia 911, es a mes vencido.
B18: INSTRUCCIONES DE LLENADO
B19: 1 | C19: Elija la Hoja que corresponda al Centro de Atencion a Llamadas de Emergencia a reportar
B20: 2 | C20: En el espacio "MES", elija el mes (vencido) de la información que se remite en el archivo electrónico al Centro Nacional de Información.
B21: 3 | C21: Ingrese en la columna "cantidad" el número total de eventos occurridos
C23: Una vez concluida su captura, guarde los cambios y envíe al correo electrónico correspondiente

Sheet Lista
C4: Estados | E4: Año | G4: Mes | I4: Administración
C5: AGUASCALIENTES | E5: 2010 | G5: Enero | I5: Estatal
C6: BAJA CALIFORNIA | E6: 2011 | G6: Febrero | I6: Municipal
C7: BAJA CALIFORNIA SUR | E7: 2012 | G7: Marzo
C8: CAMPECHE | E8: 2013 | G8: Abril
C9: COAHUILA | E9: 2014 | G9: Mayo
C10: COLIMA | E10: 2015 | G10: Junio
C11: CHIAPAS | E11: 2016 | G11: Julio
C12: CHIHUAHUA | E12: 2017 | G12: Agosto
C13: DISTRITO FEDERAL | E13: 2018 | G13: Septiembre
C14: DURANGO | G14: Octubre
C15: GUANAJUATO | G15: Noviembre
C16: GUERRERO | G16: Diciembre
C17: HIDALGO
C18: JALISCO
C19: MÉXICO
C20: MICHOACÁN
C21: MORELOS
C22: NAYARIT
C23: NUEVO LEÓN
C24: OAXACA
C25: PUEBLA
C26: QUERÉTARO
C27: QUINTANA ROO
C28: SAN LUIS POTOSÍ
... C36: ZACATECAS

Sheet Datos
A1: ENTIDAD | B1: Mes | C1: Administración
A2: Aguascalientes | B2: Enero | C2: Estatal
A3: Baja California | B3: Febrero | C3: Federal
A4: Baja California Sur | B4: Marzo
A5: Campeche | B5: Abril
A6: Coahuila de Zaragoza | B6: Mayo
A7: Colima | B7: Junio
A8: Chiapas | B8: Julio
A9: Chihuahua | B9: Agosto
A10: Distrito Federal | B10: Septiembre
A11: Durango | B11: Octubre
A12: Guanajuato | B12: Noviembre
A13: Guerrero | B13: Diciembre
A14: Hidalgo | B14: Enero
A15: Jalisco | B15: Febrero
... A25: San Luis Potosí | B25: Diciembre
A26: Sinaloa
A27: Sonora
A28: Tabasco
A29: Tamaulipas
A30: Tlaxcala
A31: Veracruz de Ignacio de la Llave
A32: Yucatán
A33: Zacatecas

Sheet RESUMEN
B4: SECRETARIA DE SEGURIDAD Y PROTECCIÓN CIUDADANA
B5: SECRETARIADO EJECUTIVO DEL SISTEMA NACIONAL DE SEGURIDAD PUBLICA
B6: CENTRO NACIONAL DE INFORMACIÓN
A8: RESUMEN ESTATAL DE LLAMADAS DE EMERGENCIA
B10: Nombre de la Entidad Federativa: | C10: Guanajuato
B11: Año: | C11: 2026
B12: Mes: | C12: Julio
B13: Total de Llamadas: | C13: =A16+B16+C16+D16+E16+F16+G16 -> 317663
A15: Total de Llamadas por Tipo Médico | B15: Total de Llamadas por Tipo Protección Civil | C15: Total de Llamadas por Tipo Seguridad | D15: Total de Llamadas por Tipo Servicios Públicos | E15: Total de Llamadas por Tipo Asistencia | F15: Total de Llamadas por Tipo Otros Servicios | G15: Total de Llamadas por Tipo Improcedentes
A16: =SUM('C01'!D20:'C01'!D79,'C02'!D20:'C02'!D79,'C03'!D20:'C03'!D79,'C04'!D20:'C04'!D79,'C05'!D20:'C05'!D79,'C06'!D20:'C06'!D79,'C07'!D20:'C07'!D79,'C08'!D20:'C08'!D79,'C09'!D20:'C09'!D79,'C010'!D20:'C010'!D79,'C011'!D20:'C011'!D79,'C012'!D20:'C012'!D79,'C013'!D20:'C013'!D79,'C014'!D20:'C014'!D79,'C015'!D20:'C015'!D79,'C016'!D20:'C016'!D79,'C017'!D20:'C017'!D79,'C018'!D20:'C018'!D79,'C019'!D20:'C019'!D79,'C020'!D20:'C020'!D79,'C021'!D20:'C021'!D79,'C022'!D20:'C022'!D79,'C023'!D20:'C023'!D79,'C024'!D20:'C024'!D79,'C025'!D20:'C025'!D79,'C026'!D20:'C026'!D79,'C027'!D20:'C027'!D79,'C028'!D20:'C028'!D79,'C029'!D20:'C029'!D79,'C030'!D20:'C030'!D79,'C031'!D20:'C031'!D79,'C032'!D20:'C032'!D79,'C033'!D20:'C033'!D79,'C034'!D20:'C034'!D79,'C035'!D20:'C035'!D79,'C036'!D20:'C036'!D79,'C037'!D20:'C037'!D79,'C038'!D20:'C038'!D79,'C039'!D20:'C039'!D79,'C040'!D20:'C040'!D79,'C041'!D20:'C041'!D79,'C042'!D20:'C042'!D79,'C043'!D20:'C043'!D79) -> 12679 | B16: =SUM('C01'!D80:'C01'!D122,'C02'!D80:'C02'!D122,'C03'!D80:'C03'!D122,'C04'!D80:'C04'!D122,'C05'!D80:'C05'!D122,'C06'!D80:'C06'!D122,'C07'!D80:'C07'!D122,'C08'!D80:'C08'!D122,'C09'!D80:'C09'!D122,'C010'!D80:'C010'!D122,'C011'!D80:'C011'!D122,'C012'!D80:'C012'!D122,'C013'!D80:'C013'!D122,'C014'!D80:'C014'!D122,'C015'!D80:'C015'!D122,'C016'!D80:'C016'!D122,'C017'!D80:'C017'!D122,'C018'!D80:'C018'!D122,'C019'!D80:'C019'!D122,'C020'!D80:'C020'!D122,'C021'!D80:'C021'!D122,'C022'!D80:'C022'!D122,'C023'!D80:'C023'!D122,'C024'!D80:'C024'!D122,'C025'!D80:'C025'!D122,'C026'!D80:'C026'!D122,'C027'!D80:'C027'!D122,'C028'!D80:'C028'!D122,'C029'!D80:'C029'!D122,'C030'!D80:'C030'!D122,'C031'!D80:'C031'!D122,'C032'!D80:'C032'!D122,'C033'!D80:'C033'!D122,'C034'!D80:'C034'!D122,'C035'!D80:'C035'!D122,'C036'!D80:'C036'!D122,'C037'!D80:'C037'!D122,'C038'!D80:'C038'!D122,'C039'!D80:'C039'!D122,'C040'!D80:'C040'!D122,'C041'!D80:'C041'!D122,'C042'!D80:'C042'!D122,'C043'!D80:'C043'!D122) -> 6589 | C16: =SUM('C01'!D123:'C01'!D263,'C02'!D123:'C02'!D263,'C03'!D123:'C03'!D263,'C04'!D123:'C04'!D263,'C05'!D123:'C05'!D263,'C06'!D123:'C06'!D263,'C07'!D123:'C07'!D263,'C08'!D123:'C08'!D263,'C09'!D123:'C09'!D263,'C010'!D123:'C010'!D263,'C011'!D123:'C011'!D263,'C012'!D123:'C012'!D263,'C013'!D123:'C013'!D263,'C014'!D123:'C014'!D263,'C015'!D123:'C015'!D263,'C016'!D123:'C016'!D263,'C017'!D123:'C017'!D263,'C018'!D123:'C018'!D263,'C019'!D123:'C019'!D263,'C020'!D123:'C020'!D263,'C021'!D123:'C021'!D263,'C022'!D123:'C022'!D263,'C023'!D123:'C023'!D263,'C024'!D123:'C024'!D263,'C025'!D123:'C025'!D263,'C026'!D123:'C026'!D263,'C027'!D123:'C027'!D263,'C028'!D123:'C028'!D263,'C029'!D123:'C029'!D263,'C030'!D123:'C030'!D263,'C031'!D123:'C031'!D263,'C032'!D123:'C032'!D263,'C033'!D123:'C033'!D263,'C034'!D123:'C034'!D263,'C035'!D123:'C035'!D263,'C036'!D123:'C036'!D263,'C037'!D123:'C037'!D263,'C038'!D123:'C038'!D263,'C039'!D123:'C039'!D263,'C040'!D123:'C040'!D263,'C041'!D123:'C041'!D263,'C042'!D123:'C042'!D263,'C043'!D123:'C043'!D263) -> 60413 | D16: =SUM('C01'!D264:D273,'C02'!D264:D273,'C03'!D264:D273,'C04'!D264:D273,'C05'!D264:D273,'C06'!D264:D273,'C07'!D264:D273,'C08'!D264:D273,'C09'!D264:D273,'C010'!D264:D273,'C011'!D264:D273,'C012'!D264:D273,'C013'!D264:D273,'C014'!D264:D273,'C015'!D264:D273,'C016'!D264:D273,'C017'!D264:D273,'C018'!D264:D273,'C019'!D264:D273,'C020'!D264:D273,'C021'!D264:D273,'C022'!D264:D273,'C023'!D264:D273,'C024'!D264:D273,'C025'!D264:D273,'C026'!D264:D273,'C027'!D264:D273,'C028'!D264:D273,'C029'!D264:D273,'C030'!D264:D273,'C031'!D264:D273,'C032'!D264:D273,'C033'!D264:D273,'C034'!D264:D273,'C035'!D264:D273,'C036'!D264:D273,'C037'!D264:D273,'C038'!D264:D273,'C039'!D264:D273,'C040'!D264:D273,'C041'!D264:D273,'C042'!D264:D273,'C043'!D264:D273) -> 1932 | E16: =SUM('C01'!D274:'C01'!D290,'C02'!D274:'C02'!D290,'C03'!D274:'C03'!D290,'C04'!D274:'C04'!D290,'C05'!D274:'C05'!D290,'C06'!D274:'C06'!D290,'C07'!D274:'C07'!D290,'C08'!D274:'C08'!D290,'C09'!D274:'C09'!D290,'C010'!D274:'C010'!D290,'C011'!D274:'C011'!D290,'C012'!D274:'C012'!D290,'C013'!D274:'C013'!D290,'C014'!D274:'C014'!D290,'C015'!D274:'C015'!D290,'C016'!D274:'C016'!D290,'C017'!D274:'C017'!D290,'C018'!D274:'C018'!D290,'C019'!D274:'C019'!D290,'C020'!D274:'C020'!D290,'C021'!D274:'C021'!D290,'C022'!D274:'C022'!D290,'C023'!D274:'C023'!D290,'C024'!D274:'C024'!D290,'C025'!D274:'C025'!D290,'C026'!D274:'C026'!D290,'C027'!D274:'C027'!D290,'C028'!D274:'C028'!D290,'C029'!D274:'C029'!D290,'C030'!D274:'C030'!D290,'C031'!D274:'C031'!D290,'C032'!D274:'C032'!D290,'C033'!D274:'C033'!D290,'C034'!D274:'C034'!D290,'C035'!D274:'C035'!D290,'C036'!D274:'C036'!D290,'C037'!D274:'C037'!D290,'C038'!D274:'C038'!D290,'C039'!D274:'C039'!D290,'C040'!D274:'C040'!D290,'C041'!D274:'C041'!D290,'C042'!D274:'C042'!D290,'C043'!D274:'C043'!D290) -> 16311 | F16: =SUM('C01'!D291:'C01'!D293,'C02'!D291:'C02'!D293,'C03'!D291:'C03'!D293,'C04'!D291:'C04'!D293,'C05'!D291:'C05'!D293,'C06'!D291:'C06'!D293,'C07'!D291:'C07'!D293,'C08'!D291:'C08'!D293,'C09'!D291:'C09'!D293,'C010'!D291:'C010'!D293,'C011'!D291:'C011'!D293,'C012'!D291:'C012'!D293,'C013'!D291:'C013'!D293,'C014'!D291:'C014'!D293,'C015'!D291:'C015'!D293,'C016'!D291:'C016'!D293,'C017'!D291:'C017'!D293,'C018'!D291:'C018'!D293,'C019'!D291:'C019'!D293,'C020'!D291:'C020'!D293,'C021'!D291:'C021'!D293,'C022'!D291:'C022'!D293,'C023'!D291:'C023'!D293,'C024'!D291:'C024'!D293,'C025'!D291:'C025'!D293,'C026'!D291:'C026'!D293,'C027'!D291:'C027'!D293,'C028'!D291:'C028'!D293,'C029'!D291:'C029'!D293,'C030'!D291:'C030'!D293,'C031'!D291:'C031'!D293,'C032'!D291:'C032'!D293,'C033'!D291:'C033'!D293,'C034'!D291:'C034'!D293,'C035'!D291:'C035'!D293,'C036'!D291:'C036'!D293,'C037'!D291:'C037'!D293,'C038'!D291:'C038'!D293,'C039'!D291:'C039'!D293,'C040'!D291:'C040'!D293,'C041'!D291:'C041'!D293,'C042'!D291:'C042'!D293,'C043'!D291:'C043'!D293) -> 5984 | G16: =SUM('C01'!D294:'C01'!D301,'C02'!D294:'C02'!D301,'C03'!D294:'C03'!D301,'C04'!D294:'C04'!D301,'C05'!D294:'C05'!D301,'C06'!D294:'C06'!D301,'C07'!D294:'C07'!D301,'C08'!D294:'C08'!D301,'C09'!D294:'C09'!D301,'C010'!D294:'C010'!D301,'C011'!D294:'C011'!D301,'C012'!D294:'C012'!D301,'C013'!D294:'C013'!D301,'C014'!D294:'C014'!D301,'C015'!D294:'C015'!D301,'C016'!D294:'C016'!D301,'C017'!D294:'C017'!D301,'C018'!D294:'C018'!D301,'C019'!D294:'C019'!D301,'C020'!D294:'C020'!D301,'C021'!D294:'C021'!D301,'C022'!D294:'C022'!D301,'C023'!D294:'C023'!D301,'C024'!D294:'C024'!D301,'C025'!D294:'C025'!D301,'C026'!D294:'C026'!D301,'C027'!D294:'C027'!D301,'C028'!D294:'C028'!D301,'C029'!D294:'C029'!D301,'C030'!D294:'C030'!D301,'C031'!D294:'C031'!D301,'C032'!D294:'C032'!D301,'C033'!D294:'C033'!D301,'C034'!D294:'C034'!D301,'C035'!D294:'C035'!D301,'C036'!D294:'C036'!D301,'C037'!D294:'C037'!D301,'C038'!D294:'C038'!D301,'C039'!D294:'C039'!D301,'C040'!D294:'C040'!D301,'C041'!D294:'C041'!D301,'C042'!D294:'C042'!D301,'C043'!D294:'C043'!D301) -> 213755
A19: Porcentaje de Llamadas por tipo Médico | B19: Porcentaje de Llamadas por Tipo Protección Civil | C19: Porcentaje de Llamadas por Tipo Seguridad | D19: Porcentaje de Llamadas por Tipo Servicios Públicos | E19: Porcentaje de Llamadas por Tipo Asistencia | F19: Porcentaje de Llamadas por Tipo Otros Servicios | G19: Porcentaje de Llamadas por Tipo Improcedentes
A20: =IFERROR(A16/$C$13,0) -> 0.039913367 | B20: =IFERROR(B16/$C$13,0) -> 0.020742107 | C20: =IFERROR(C16/$C$13,0) -> 0.19017953 | D20: =IFERROR(D16/$C$13,0) -> 0.006081917 | E20: =IFERROR(E16/$C$13,0) -> 0.051346868 | F20: =IFERROR(F16/$C$13,0) -> 0.018837573 | G20: =IFERROR(G16/$C$13,0) -> 0.67289864

Sheet C01
B6: SECRETARIA DE SEGURIDAD Y PROTECCIÓN CIUDADANA
B7: SECRETARIADO EJECUTIVO DEL SISTEMA NACIONAL DE SEGURIDAD PUBLICA
B8: CENTRO NACIONAL DE INFORMACIÓN
B10: (FORMATO ELECTRÓNICO FESE V.2.0)
C12: Nombre de la Entidad Federativa: | D12: =RESUMEN!C10 -> Guanajuato
C13: Año: | D13: =RESUMEN!C11 -> 2026
C14: Mes: | D14: =RESUMEN!C12 -> Julio
B16: CENTRO DE ATENCIÓN DE LLAMADAS DE EMERGENCIAS
B17: Tipo de Administración: | D17: Municipal
B18: Nombre del Centro: | D18: Abasolo
B19: ID | C19: Incidente | D19: Cantidad
B20: 10101 | C20: ACCIDENTE ACUÁTICO CON LESIONADOS | D20: 0
B21: 10102 | C21: ACCIDENTE DE AERONAVE CON LESIONADOS | D21: 0
B22: 10103 | C22: ACCIDENTE DE MOTOCICLETA CON LESIONADOS | D22: 18
B23: 10104 | C23: ACCIDENTE DE VEHÍCULO AUTOMOTOR CON LESIONADOS | D23: 0
B24: 10105 | C24: ACCIDENTE FERROVIARIO CON LESIONADOS | D24: 0
B25: 10106 | C25: ACCIDENTE FERROVIARIO CON FALLECIDO | D25: 0
B26: 10107 | C26: ACCIDENTE MÚLTIPLE CON LESIONADOS | D26: 12
B27: 10108 | C27: ACCIDENTE MÚLTIPLE CON FALLECIDO | D27: 0
B28: 10109 | C28: ACCIDENTE DE VEHÍCULO DE PASAJEROS CON LESIONADOS | D28: 0
B29: 10110 | C29: ACCIDENTE DE VEHÍCULO DE PASAJEROS CON FALLECIDO | D29: 0
B30: 10111 | C30: ACCIDENTE DE MOTOCICLETA CON FALLECIDO | D30: 0
B31: 10112 | C31: ACCIDENTE DE VEHÍCULO AUTOMOTOR CON FALLECIDO | D31: 0
... B301: 70108 | C301: OTRAS LLAMADAS DE NO EMERGENCIA | D301: 0
B302: Total | D302: =SUM(D20:D301) -> 3687

Sheet C02
B6: SECRETARIA DE SEGURIDAD Y PROTECCIÓN CIUDADANA
B7: SECRETARIADO EJECUTIVO DEL SISTEMA NACIONAL DE SEGURIDAD PUBLICA
B8: CENTRO NACIONAL DE INFORMACIÓN
B10: (FORMATO ELECTRÓNICO FESE V.2.0)
C12: Nombre de la Entidad Federativa: | D12: =RESUMEN!C10 -> Guanajuato
C13: Año: | D13: =RESUMEN!C11 -> 2026
C14: Mes: | D14: =RESUMEN!C12 -> Julio
B16: CENTRO DE ATENCIÓN DE LLAMADAS DE EMERGENCIAS
B17: Tipo de Administración: | D17: Municipal
B18: Nombre del Centro: | D18: Acambaro
B19: ID | C19: Incidente | D19: Cantidad
B20: 10101 | C20: ACCIDENTE ACUÁTICO CON LESIONADOS | D20: 0
B21: 10102 | C21: ACCIDENTE DE AERONAVE CON LESIONADOS | D21: 0
B22: 10103 | C22: ACCIDENTE DE MOTOCICLETA CON LESIONADOS | D22: 33
B23: 10104 | C23: ACCIDENTE DE VEHÍCULO AUTOMOTOR CON LESIONADOS | D23: 0
B24: 10105 | C24: ACCIDENTE FERROVIARIO CON LESIONADOS | D24: 0
B25: 10106 | C25: ACCIDENTE FERROVIARIO CON FALLECIDO | D25: 0
B26: 10107 | C26: ACCIDENTE MÚLTIPLE CON LESIONADOS | D26: 62
B27: 10108 | C27: ACCIDENTE MÚLTIPLE CON FALLECIDO | D27: 0
B28: 10109 | C28: ACCIDENTE DE VEHÍCULO DE PASAJEROS CON LESIONADOS | D28: 0
B29: 10110 | C29: ACCIDENTE DE VEHÍCULO DE PASAJEROS CON FALLECIDO | D29: 0
B30: 10111 | C30: ACCIDENTE DE MOTOCICLETA CON FALLECIDO | D30: 0
B31: 10112 | C31: ACCIDENTE DE VEHÍCULO AUTOMOTOR CON FALLECIDO | D31: 0
... B301: 70108 | C301: OTRAS LLAMADAS DE NO EMERGENCIA | D301: 1152
B302: Total | D302: =SUM(D20:D301) -> 5404

Sheet C03
B6: SECRETARIA DE SEGURIDAD Y PROTECCIÓN CIUDADANA
B7: SECRETARIADO EJECUTIVO DEL SISTEMA NACIONAL DE SEGURIDAD PUBLICA
B8: CENTRO NACIONAL DE INFORMACIÓN
B10: (FORMATO ELECTRÓNICO FESE V.2.0)
C12: Nombre de la Entidad Federativa: | D12: =RESUMEN!C10 -> Guanajuato
C13: Año: | D13: =RESUMEN!C11 -> 2026
C14: Mes: | D14: =RESUMEN!C12 -> Julio
B16: CENTRO DE ATENCIÓN DE LLAMADAS DE EMERGENCIAS
B17: Tipo de Administración: | D17: Municipal
B18: Nombre del Centro: | D18: San Miguel de Allende
B19: ID | C19: Incidente | D19: Cantidad
B20: 10101 | C20: ACCIDENTE ACUÁTICO CON LESIONADOS | D20: 0
B21: 10102 | C21: ACCIDENTE DE AERONAVE CON LESIONADOS | D21: 0
B22: 10103 | C22: ACCIDENTE DE MOTOCICLETA CON LESIONADOS | D22: 48
B23: 10104 | C23: ACCIDENTE DE VEHÍCULO AUTOMOTOR CON LESIONADOS | D23: 0
B24: 10105 | C24: ACCIDENTE FERROVIARIO CON LESIONADOS | D24: 0
B25: 10106 | C25: ACCIDENTE FERROVIARIO CON FALLECIDO | D25: 0
B26: 10107 | C26: ACCIDENTE MÚLTIPLE CON LESIONADOS | D26: 157
B27: 10108 | C27: ACCIDENTE MÚLTIPLE CON FALLECIDO | D27: 0
B28: 10109 | C28: ACCIDENTE DE VEHÍCULO DE PASAJEROS CON LESIONADOS | D28: 0
B29: 10110 | C29: ACCIDENTE DE VEHÍCULO DE PASAJEROS CON FALLECIDO | D29: 0
B30: 10111 | C30: ACCIDENTE DE MOTOCICLETA CON FALLECIDO | D30: 0
B31: 10112 | C31: ACCIDENTE DE VEHÍCULO AUTOMOTOR CON FALLECIDO | D31: 0
... B301: 70108 | C301: OTRAS LLAMADAS DE NO EMERGENCIA | D301: 4336
B302: Total | D302: =SUM(D20:D301) -> 17070

Sheet C04
B6: SECRETARIA DE SEGURIDAD Y PROTECCIÓN CIUDADANA
B7: SECRETARIADO EJECUTIVO DEL SISTEMA NACIONAL DE SEGURIDAD PUBLICA
B8: CENTRO NACIONAL DE INFORMACIÓN
B10: (FORMATO ELECTRÓNICO FESE V.2.0)
C12: Nombre de la Entidad Federativa: | D12: =RESUMEN!C10 -> Guanajuato
C13: Año: | D13: =RESUMEN!C11 -> 2026
C14: Mes: | D14: =RESUMEN!C12 -> Julio
B16: CENTRO DE ATENCIÓN DE LLAMADAS DE EMERGENCIAS
B17: Tipo de Administración: | D17: Municipal
B18: Nombre del Centro: | D18: Apaseo el Alto
B19: ID | C19: Incidente | D19: Cantidad
B20: 10101 | C20: ACCIDENTE ACUÁTICO CON LESIONADOS | D20: 0
B21: 10102 | C21: ACCIDENTE DE AERONAVE CON LESIONADOS | D21: 0
B22: 10103 | C22: ACCIDENTE DE MOTOCICLETA CON LESIONADOS | D22: 15
B23: 10104 | C23: ACCIDENTE DE VEHÍCULO AUTOMOTOR CON LESIONADOS | D23: 0
B24: 10105 | C24: ACCIDENTE FERROVIARIO CON LESIONADOS | D24: 0
B25: 10106 | C25: ACCIDENTE FERROVIARIO CON FALLECIDO | D25: 0
B26: 10107 | C26: ACCIDENTE MÚLTIPLE CON LESIONADOS | D26: 2
B27: 10108 | C27: ACCIDENTE MÚLTIPLE CON FALLECIDO | D27: 0
B28: 10109 | C28: ACCIDENTE DE VEHÍCULO DE PASAJEROS CON LESIONADOS | D28: 0
B29: 10110 | C29: ACCIDENTE DE VEHÍCULO DE PASAJEROS CON FALLECIDO | D29: 0
B30: 10111 | C30: ACCIDENTE DE MOTOCICLETA CON FALLECIDO | D30: 0
B31: 10112 | C31: ACCIDENTE DE VEHÍCULO AUTOMOTOR CON FALLECIDO | D31: 0
... B301: 70108 | C301: OTRAS LLAMADAS DE NO EMERGENCIA | D301: 1340
B302: Total | D302: =SUM(D20:D301) -> 2761

Sheet C05
B6: SECRETARIA DE SEGURIDAD Y PROTECCIÓN CIUDADANA
B7: SECRETARIADO EJECUTIVO DEL SISTEMA NACIONAL DE SEGURIDAD PUBLICA
B8: CENTRO NACIONAL DE INFORMACIÓN
B10: (FORMATO ELECTRÓNICO FESE V.2.0)
C12: Nombre de la Entidad Federativa: | D12: =RESUMEN!C10 -> Guanajuato
C13: Año: | D13: =RESUMEN!C11 -> 2026
C14: Mes: | D14: =RESUMEN!C12 -> Julio
B16: CENTRO DE ATENCIÓN DE LLAMADAS DE EMERGENCIAS
B17: Tipo de Administración: | D17: Municipal
B18: Nombre del Centro: | D18: Apaseo el Grande
B19: ID | C19: Incidente | D19: Cantidad
B20: 10101 | C20: ACCIDENTE ACUÁTICO CON LESIONADOS | D20: 0
B21: 10102 | C21: ACCIDENTE DE AERONAVE CON LESIONADOS | D21: 0
B22: 10103 | C22: ACCIDENTE DE MOTOCICLETA CON LESIONADOS | D22: 34
B23: 10104 | C23: ACCIDENTE DE VEHÍCULO AUTOMOTOR CON LESIONADOS | D23: 0
B24: 10105 | C24: ACCIDENTE FERROVIARIO CON LESIONADOS | D24: 0
B25: 10106 | C25: ACCIDENTE FERROVIARIO CON FALLECIDO | D25: 0
B26: 10107 | C26: ACCIDENTE MÚLTIPLE CON LESIONADOS | D26: 12
B27: 10108 | C27: ACCIDENTE MÚLTIPLE CON FALLECIDO | D27: 0
B28: 10109 | C28: ACCIDENTE DE VEHÍCULO DE PASAJEROS CON LESIONADOS | D28: 0
B29: 10110 | C29: ACCIDENTE DE VEHÍCULO DE PASAJEROS CON FALLECIDO | D29: 0
B30: 10111 | C30: ACCIDENTE DE MOTOCICLETA CON FALLECIDO | D30: 1
B31: 10112 | C31: ACCIDENTE DE VEHÍCULO AUTOMOTOR CON FALLECIDO | D31: 0
... B301: 70108 | C301: OTRAS LLAMADAS DE NO EMERGENCIA | D301: 2087
B302: Total | D302: =SUM(D20:D301) -> 6512

Sheet C06
B6: SECRETARIA DE SEGURIDAD Y PROTECCIÓN CIUDADANA
B7: SECRETARIADO EJECUTIVO DEL SISTEMA NACIONAL DE SEGURIDAD PUBLICA
B8: CENTRO NACIONAL DE INFORMACIÓN
B10: (FORMATO ELECTRÓNICO FESE V.2.0)
C12: Nombre de la Entidad Federativa: | D12: =RESUMEN!C10 -> Guanajuato
C13: Año: | D13: =RESUMEN!C11 -> 2026
C14: Mes: | D14: =RESUMEN!C12 -> Julio
B16: CENTRO DE ATENCIÓN DE LLAMADAS DE EMERGENCIAS
B17: Tipo de Administración: | D17: Municipal
B18: Nombre del Centro: | D18: Cd. Manuel Doblado
B19: ID | C19: Incidente | D19: Cantidad
B20: 10101 | C20: ACCIDENTE ACUÁTICO CON LESIONADOS | D20: 0
B21: 10102 | C21: ACCIDENTE DE AERONAVE CON LESIONADOS | D21: 0
B22: 10103 | C22: ACCIDENTE DE MOTOCICLETA CON LESIONADOS | D22: 14
B23: 10104 | C23: ACCIDENTE DE VEHÍCULO AUTOMOTOR CON LESIONADOS | D23: 0
B24: 10105 | C24: ACCIDENTE FERROVIARIO CON LESIONADOS | D24: 0
B25: 10106 | C25: ACCIDENTE FERROVIARIO CON FALLECIDO | D25: 0
B26: 10107 | C26: ACCIDENTE MÚLTIPLE CON LESIONADOS | D26: 7
B27: 10108 | C27: ACCIDENTE MÚLTIPLE CON FALLECIDO | D27: 0
B28: 10109 | C28: ACCIDENTE DE VEHÍCULO DE PASAJEROS CON LESIONADOS | D28: 0
B29: 10110 | C29: ACCIDENTE DE VEHÍCULO DE PASAJEROS CON FALLECIDO | D29: 0
B30: 10111 | C30: ACCIDENTE DE MOTOCICLETA CON FALLECIDO | D30: 0
B31: 10112 | C31: ACCIDENTE DE VEHÍCULO AUTOMOTOR CON FALLECIDO | D31: 0
... B301: 70108 | C301: OTRAS LLAMADAS DE NO EMERGENCIA | D301: 373
B302: Total | D302: =SUM(D20:D301) -> 1444

Sheet C07
B6: SECRETARIA DE SEGURIDAD Y PROTECCIÓN CIUDADANA
B7: SECRETARIADO EJECUTIVO DEL SISTEMA NACIONAL DE SEGURIDAD PUBLICA
B8: CENTRO NACIONAL DE INFORMACIÓN
B10: (FORMATO ELECTRÓNICO FESE V.2.0)
C12: Nombre de la Entidad Federativa: | D12: =RESUMEN!C10 -> Guanajuato
C13: Año: | D13: =RESUMEN!C11 -> 2026
C14: Mes: | D14: =RESUMEN!C12 -> Julio
B16: CENTRO DE ATENCIÓN DE LLAMADAS DE EMERGENCIAS
B17: Tipo de Administración: | D17: Municipal
B18: Nombre del Centro: | D18: Celaya
B19: ID | C19: Incidente | D19: Cantidad
B20: 10101 | C20: ACCIDENTE ACUÁTICO CON LESIONADOS | D20: 0
B21: 10102 | C21: ACCIDENTE DE AERONAVE CON LESIONADOS | D21: 1
B22: 10103 | C22: ACCIDENTE DE MOTOCICLETA CON LESIONADOS | D22: 109
B23: 10104 | C23: ACCIDENTE DE VEHÍCULO AUTOMOTOR CON LESIONADOS | D23: 0
B24: 10105 | C24: ACCIDENTE FERROVIARIO CON LESIONADOS | D24: 1
B25: 10106 | C25: ACCIDENTE FERROVIARIO CON FALLECIDO | D25: 0
B26: 10107 | C26: ACCIDENTE MÚLTIPLE CON LESIONADOS | D26: 197
B27: 10108 | C27: ACCIDENTE MÚLTIPLE CON FALLECIDO | D27: 0
B28: 10109 | C28: ACCIDENTE DE VEHÍCULO DE PASAJEROS CON LESIONADOS | D28: 0
B29: 10110 | C29: ACCIDENTE DE VEHÍCULO DE PASAJEROS CON FALLECIDO | D29: 0
B30: 10111 | C30: ACCIDENTE DE MOTOCICLETA CON FALLECIDO | D30: 0
B31: 10112 | C31: ACCIDENTE DE VEHÍCULO AUTOMOTOR CON FALLECIDO | D31: 0
... B301: 70108 | C301: OTRAS LLAMADAS DE NO EMERGENCIA | D301: 8215
B302: Total | D302: =SUM(D20:D301) -> 19983

Sheet C08
B6: SECRETARIA DE SEGURIDAD Y PROTECCIÓN CIUDADANA
B7: SECRETARIADO EJECUTIVO DEL SISTEMA NACIONAL DE SEGURIDAD PUBLICA
B8: CENTRO NACIONAL DE INFORMACIÓN
B10: (FORMATO ELECTRÓNICO FESE V.2.0)
C12: Nombre de la Entidad Federativa: | D12: =RESUMEN!C10 -> Guanajuato
C13: Año: | D13: =RESUMEN!C11 -> 2026
C14: Mes: | D14: =RESUMEN!C12 -> Julio
B16: CENTRO DE ATENCIÓN DE LLAMADAS DE EMERGENCIAS
B17: Tipo de Administración: | D17: Municipal
B18: Nombre del Centro: | D18: Comonfort
B19: ID | C19: Incidente | D19: 0
B20: 10101 | C20: ACCIDENTE ACUÁTICO CON LESIONADOS | D20: 0
B21: 10102 | C21: ACCIDENTE DE AERONAVE CON LESIONADOS | D21: 0
B22: 10103 | C22: ACCIDENTE DE MOTOCICLETA CON LESIONADOS | D22: 23
B23: 10104 | C23: ACCIDENTE DE VEHÍCULO AUTOMOTOR CON LESIONADOS | D23: 1
B24: 10105 | C24: ACCIDENTE FERROVIARIO CON LESIONADOS | D24: 0
B25: 10106 | C25: ACCIDENTE FERROVIARIO CON FALLECIDO | D25: 0
B26: 10107 | C26: ACCIDENTE MÚLTIPLE CON LESIONADOS | D26: 5
B27: 10108 | C27: ACCIDENTE MÚLTIPLE CON FALLECIDO | D27: 0
B28: 10109 | C28: ACCIDENTE DE VEHÍCULO DE PASAJEROS CON LESIONADOS | D28: 0
B29: 10110 | C29: ACCIDENTE DE VEHÍCULO DE PASAJEROS CON FALLECIDO | D29: 0
B30: 10111 | C30: ACCIDENTE DE MOTOCICLETA CON FALLECIDO | D30: 0
B31: 10112 | C31: ACCIDENTE DE VEHÍCULO AUTOMOTOR CON FALLECIDO | D31: 0
... B301: 70108 | C301: OTRAS LLAMADAS DE NO EMERGENCIA | D301: 1225
B302: Total | D302: =SUM(D20:D301) -> 3541

Sheet C09
B6: SECRETARIA DE SEGURIDAD Y PROTECCIÓN CIUDADANA
B7: SECRETARIADO EJECUTIVO DEL SISTEMA NACIONAL DE SEGURIDAD PUBLICA
B8: CENTRO NACIONAL DE INFORMACIÓN
B10: (FORMATO ELECTRÓNICO FESE V.2.0)
C12: Nombre de la Entidad Federativa: | D12: =RESUMEN!C10 -> Guanajuato
C13: Año: | D13: =RESUMEN!C11 -> 2026
C14: Mes: | D14: =RESUMEN!C12 -> Julio
B16: CENTRO DE ATENCIÓN DE LLAMADAS DE EMERGENCIAS
B17: Tipo de Administración: | D17: Municipal
B18: Nombre del Centro: | D18: Coroneo
B19: ID | C19: Incidente | D19: Cantidad
B20: 10101 | C20: ACCIDENTE ACUÁTICO CON LESIONADOS | D20: 0
B21: 10102 | C21: ACCIDENTE DE AERONAVE CON LESIONADOS | D21: 0
B22: 10103 | C22: ACCIDENTE DE MOTOCICLETA CON LESIONADOS | D22: 3
B23: 10104 | C23: ACCIDENTE DE VEHÍCULO AUTOMOTOR CON LESIONADOS | D23: 0
B24: 10105 | C24: ACCIDENTE FERROVIARIO CON LESIONADOS | D24: 0
B25: 10106 | C25: ACCIDENTE FERROVIARIO CON FALLECIDO | D25: 0
B26: 10107 | C26: ACCIDENTE MÚLTIPLE CON LESIONADOS | D26: 2
B27: 10108 | C27: ACCIDENTE MÚLTIPLE CON FALLECIDO | D27: 0
B28: 10109 | C28: ACCIDENTE DE VEHÍCULO DE PASAJEROS CON LESIONADOS | D28: 0
B29: 10110 | C29: ACCIDENTE DE VEHÍCULO DE PASAJEROS CON FALLECIDO | D29: 0
B30: 10111 | C30: ACCIDENTE DE MOTOCICLETA CON FALLECIDO | D30: 0
B31: 10112 | C31: ACCIDENTE DE VEHÍCULO AUTOMOTOR CON FALLECIDO | D31: 0
... B301: 70108 | C301: OTRAS LLAMADAS DE NO EMERGENCIA | D301: 63
B302: Total | D302: =SUM(D20:D301) -> 354

Sheet C010
B6: SECRETARIA DE SEGURIDAD Y PROTECCIÓN CIUDADANA
B7: SECRETARIADO EJECUTIVO DEL SISTEMA NACIONAL DE SEGURIDAD PUBLICA
B8: CENTRO NACIONAL DE INFORMACIÓN
B10: (FORMATO ELECTRÓNICO FESE V.2.0)
C12: Nombre de la Entidad Federativa: | D12: =RESUMEN!C10 -> Guanajuato
C13: Año: | D13: =RESUMEN!C11 -> 2026
C14: Mes: | D14: =RESUMEN!C12 -> Julio
B16: CENTRO DE ATENCIÓN DE LLAMADAS DE EMERGENCIAS
B17: Tipo de Administración: | D17: Municipal
B18: Nombre del Centro: | D18: Cortazar
B19: ID | C19: Incidente | D19: Cantidad
B20: 10101 | C20: ACCIDENTE ACUÁTICO CON LESIONADOS | D20: 0
B21: 10102 | C21: ACCIDENTE DE AERONAVE CON LESIONADOS | D21: 0
B22: 10103 | C22: ACCIDENTE DE MOTOCICLETA CON LESIONADOS | D22: 5
B23: 10104 | C23: ACCIDENTE DE VEHÍCULO AUTOMOTOR CON LESIONADOS | D23: 0
B24: 10105 | C24: ACCIDENTE FERROVIARIO CON LESIONADOS | D24: 0
B25: 10106 | C25: ACCIDENTE FERROVIARIO CON FALLECIDO | D25: 0
B26: 10107 | C26: ACCIDENTE MÚLTIPLE CON LESIONADOS | D26: 48
B27: 10108 | C27: ACCIDENTE MÚLTIPLE CON FALLECIDO | D27: 0
B28: 10109 | C28: ACCIDENTE DE VEHÍCULO DE PASAJEROS CON LESIONADOS | D28: 0
B29: 10110 | C29: ACCIDENTE DE VEHÍCULO DE PASAJEROS CON FALLECIDO | D29: 0
B30: 10111 | C30: ACCIDENTE DE MOTOCICLETA CON FALLECIDO | D30: 0
B31: 10112 | C31: ACCIDENTE DE VEHÍCULO AUTOMOTOR CON FALLECIDO | D31: 0
... B301: 70108 | C301: OTRAS LLAMADAS DE NO EMERGENCIA | D301: 594
B302: Total | D302: =SUM(D20:D301) -> 3646

Sheet C011
B6: SECRETARIA DE SEGURIDAD Y PROTECCIÓN CIUDADANA
B7: SECRETARIADO EJECUTIVO DEL SISTEMA NACIONAL DE SEGURIDAD PUBLICA
B8: CENTRO NACIONAL DE INFORMACIÓN
B10: (FORMATO ELECTRÓNICO FESE V.2.0)
C12: Nombre de la Entidad Federativa: | D12: =RESUMEN!C10 -> Guanajuato
C13: Año: | D13: =RESUMEN!C11 -> 2026
C14: Mes: | D14: =RESUMEN!C12 -> Julio
B16: CENTRO DE ATENCIÓN DE LLAMADAS DE EMERGENCIAS
B17: Tipo de Administración: | D17: Municipal
B18: Nombre del Centro: | D18: Cueramaro
B19: ID | C19: Incidente | D19: Cantidad
B20: 10101 | C20: ACCIDENTE ACUÁTICO CON LESIONADOS | D20: 0
B21: 10102 | C21: ACCIDENTE DE AERONAVE CON LESIONADOS | D21: 0
B22: 10103 | C22: ACCIDENTE DE MOTOCICLETA CON LESIONADOS | D22: 9
B23: 10104 | C23: ACCIDENTE DE VEHÍCULO AUTOMOTOR CON LESIONADOS | D23: 0
B24: 10105 | C24: ACCIDENTE FERROVIARIO CON LESIONADOS | D24: 0
B25: 10106 | C25: ACCIDENTE FERROVIARIO CON FALLECIDO | D25: 0
B26: 10107 | C26: ACCIDENTE MÚLTIPLE CON LESIONADOS | D26: 6
B27: 10108 | C27: ACCIDENTE MÚLTIPLE CON FALLECIDO | D27: 0
B28: 10109 | C28: ACCIDENTE DE VEHÍCULO DE PASAJEROS CON LESIONADOS | D28: 0
B29: 10110 | C29: ACCIDENTE DE VEHÍCULO DE PASAJEROS CON FALLECIDO | D29: 0
B30: 10111 | C30: ACCIDENTE DE MOTOCICLETA CON FALLECIDO | D30: 0
B31: 10112 | C31: ACCIDENTE DE VEHÍCULO AUTOMOTOR CON FALLECIDO | D31: 0
... B301: 70108 | C301: OTRAS LLAMADAS DE NO EMERGENCIA | D301: 55
B302: Total | D302: =SUM(D20:D301) -> 1407

Sheet C012
B6: SECRETARIA DE SEGURIDAD Y PROTECCIÓN CIUDADANA
B7: SECRETARIADO EJECUTIVO DEL SISTEMA NACIONAL DE SEGURIDAD PUBLICA
B8: CENTRO NACIONAL DE INFORMACIÓN
B10: (FORMATO ELECTRÓNICO FESE V.2.0)
C12: Nombre de la Entidad Federativa: | D12: =RESUMEN!C10 -> Guanajuato
C13: Año: | D13: =RESUMEN!C11 -> 2026
C14: Mes: | D14: =RESUMEN!C12 -> Julio
B16: CENTRO DE ATENCIÓN DE LLAMADAS DE EMERGENCIAS
B17: Tipo de Administración: | D17: Municipal
B18: Nombre del Centro: | D18: Dolores Hidalgo C.I.N.
B19: ID | C19: Incidente | D19: Cantidad
B20: 10101 | C20: ACCIDENTE ACUÁTICO CON LESIONADOS | D20: 0
B21: 10102 | C21: ACCIDENTE DE AERONAVE CON LESIONADOS | D21: 0
B22: 10103 | C22: ACCIDENTE DE MOTOCICLETA CON LESIONADOS | D22: 34
B23: 10104 | C23: ACCIDENTE DE VEHÍCULO AUTOMOTOR CON LESIONADOS | D23: 2
B24: 10105 | C24: ACCIDENTE FERROVIARIO CON LESIONADOS | D24: 0
B25: 10106 | C25: ACCIDENTE FERROVIARIO CON FALLECIDO | D25: 0
B26: 10107 | C26: ACCIDENTE MÚLTIPLE CON LESIONADOS | D26: 22
B27: 10108 | C27: ACCIDENTE MÚLTIPLE CON FALLECIDO | D27: 0
B28: 10109 | C28: ACCIDENTE DE VEHÍCULO DE PASAJEROS CON LESIONADOS | D28: 0
B29: 10110 | C29: ACCIDENTE DE VEHÍCULO DE PASAJEROS CON FALLECIDO | D29: 0
B30: 10111 | C30: ACCIDENTE DE MOTOCICLETA CON FALLECIDO | D30: 0
B31: 10112 | C31: ACCIDENTE DE VEHÍCULO AUTOMOTOR CON FALLECIDO | D31: 0
... B301: 70108 | C301: OTRAS LLAMADAS DE NO EMERGENCIA | D301: 3122
B302: Total | D302: =SUM(D20:D301) -> 7942

Sheet C013
B6: SECRETARIA DE SEGURIDAD Y PROTECCIÓN CIUDADANA
B7: SECRETARIADO EJECUTIVO DEL SISTEMA NACIONAL DE SEGURIDAD PUBLICA
B8: CENTRO NACIONAL DE INFORMACIÓN
B10: (FORMATO ELECTRÓNICO FESE V.2.0)
C12: Nombre de la Entidad Federativa: | D12: =RESUMEN!C10 -> Guanajuato
C13: Año: | D13: =RESUMEN!C11 -> 2026
C14: Mes: | D14: =RESUMEN!C12 -> Julio
B16: CENTRO DE ATENCIÓN DE LLAMADAS DE EMERGENCIAS
B17: Tipo de Administración: | D17: Municipal
B18: Nombre del Centro: | D18: Dr. Mora
B19: ID | C19: Incidente | D19: Cantidad
B20: 10101 | C20: ACCIDENTE ACUÁTICO CON LESIONADOS | D20: 0
B21: 10102 | C21: ACCIDENTE DE AERONAVE CON LESIONADOS | D21: 0
B22: 10103 | C22: ACCIDENTE DE MOTOCICLETA CON LESIONADOS | D22: 3
B23: 10104 | C23: ACCIDENTE DE VEHÍCULO AUTOMOTOR CON LESIONADOS | D23: 0
B24: 10105 | C24: ACCIDENTE FERROVIARIO CON LESIONADOS | D24: 0
B25: 10106 | C25: ACCIDENTE FERROVIARIO CON FALLECIDO | D25: 0
B26: 10107 | C26: ACCIDENTE MÚLTIPLE CON LESIONADOS | D26: 0
B27: 10108 | C27: ACCIDENTE MÚLTIPLE CON FALLECIDO | D27: 0
B28: 10109 | C28: ACCIDENTE DE VEHÍCULO DE PASAJEROS CON LESIONADOS | D28: 0
B29: 10110 | C29: ACCIDENTE DE VEHÍCULO DE PASAJEROS CON FALLECIDO | D29: 0
B30: 10111 | C30: ACCIDENTE DE MOTOCICLETA CON FALLECIDO | D30: 0
B31: 10112 | C31: ACCIDENTE DE VEHÍCULO AUTOMOTOR CON FALLECIDO | D31: 0
... B301: 70108 | C301: OTRAS LLAMADAS DE NO EMERGENCIA | D301: 180
B302: Total | D302: =SUM(D20:D301) -> 733

Sheet C014
B6: SECRETARIA DE SEGURIDAD Y PROTECCIÓN CIUDADANA
B7: SECRETARIADO EJECUTIVO DEL SISTEMA NACIONAL DE SEGURIDAD PUBLICA
B8: CENTRO NACIONAL DE INFORMACIÓN
B10: (FORMATO ELECTRÓNICO FESE V.2.0)
C12: Nombre de la Entidad Federativa: | D12: =RESUMEN!C10 -> Guanajuato
C13: Año: | D13: =RESUMEN!C11 -> 2026
C14: Mes: | D14: =RESUMEN!C12 -> Julio
B16: CENTRO DE ATENCIÓN DE LLAMADAS DE EMERGENCIAS
B17: Tipo de Administración: | D17: Municipal
B18: Nombre del Centro: | D18: Guanajuato
B19: ID | C19: Incidente | D19: Cantidad
B20: 10101 | C20: ACCIDENTE ACUÁTICO CON LESIONADOS | D20: 0
B21: 10102 | C21: ACCIDENTE DE AERONAVE CON LESIONADOS | D21: 0
B22: 10103 | C22: ACCIDENTE DE MOTOCICLETA CON LESIONADOS | D22: 51
B23: 10104 | C23: ACCIDENTE DE VEHÍCULO AUTOMOTOR CON LESIONADOS | D23: 0
B24: 10105 | C24: ACCIDENTE FERROVIARIO CON LESIONADOS | D24: 0
B25: 10106 | C25: ACCIDENTE FERROVIARIO CON FALLECIDO | D25: 0
B26: 10107 | C26: ACCIDENTE MÚLTIPLE CON LESIONADOS | D26: 33
B27: 10108 | C27: ACCIDENTE MÚLTIPLE CON FALLECIDO | D27: 0
B28: 10109 | C28: ACCIDENTE DE VEHÍCULO DE PASAJEROS CON LESIONADOS | D28: 0
B29: 10110 | C29: ACCIDENTE DE VEHÍCULO DE PASAJEROS CON FALLECIDO | D29: 0
B30: 10111 | C30: ACCIDENTE DE MOTOCICLETA CON FALLECIDO | D30: 0
B31: 10112 | C31: ACCIDENTE DE VEHÍCULO AUTOMOTOR CON FALLECIDO | D31: 0
... B301: 70108 | C301: OTRAS LLAMADAS DE NO EMERGENCIA | D301: 1007
B302: Total | D302: =SUM(D20:D301) -> 11742

Sheet C015
B6: SECRETARIA DE SEGURIDAD Y PROTECCIÓN CIUDADANA
B7: SECRETARIADO EJECUTIVO DEL SISTEMA NACIONAL DE SEGURIDAD PUBLICA
B8: CENTRO NACIONAL DE INFORMACIÓN
B10: (FORMATO ELECTRÓNICO FESE V.2.0)
C12: Nombre de la Entidad Federativa: | D12: =RESUMEN!C10 -> Guanajuato
C13: Año: | D13: =RESUMEN!C11 -> 2026
C14: Mes: | D14: =RESUMEN!C12 -> Julio
B16: CENTRO DE ATENCIÓN DE LLAMADAS DE EMERGENCIAS
B17: Tipo de Administración: | D17: Municipal
B18: Nombre del Centro: | D18: Huanimaro
B19: ID | C19: Incidente | D19: Cantidad
B20: 10101 | C20: ACCIDENTE ACUÁTICO CON LESIONADOS | D20: 0
B21: 10102 | C21: ACCIDENTE DE AERONAVE CON LESIONADOS | D21: 0
B22: 10103 | C22: ACCIDENTE DE MOTOCICLETA CON LESIONADOS | D22: 2
B23: 10104 | C23: ACCIDENTE DE VEHÍCULO AUTOMOTOR CON LESIONADOS | D23: 0
B24: 10105 | C24: ACCIDENTE FERROVIARIO CON LESIONADOS | D24: 0
B25: 10106 | C25: ACCIDENTE FERROVIARIO CON FALLECIDO | D25: 0
B26: 10107 | C26: ACCIDENTE MÚLTIPLE CON LESIONADOS | D26: 0
B27: 10108 | C27: ACCIDENTE MÚLTIPLE CON FALLECIDO | D27: 0
B28: 10109 | C28: ACCIDENTE DE VEHÍCULO DE PASAJEROS CON LESIONADOS | D28: 0
B29: 10110 | C29: ACCIDENTE DE VEHÍCULO DE PASAJEROS CON FALLECIDO | D29: 0
B30: 10111 | C30: ACCIDENTE DE MOTOCICLETA CON FALLECIDO | D30: 0
B31: 10112 | C31: ACCIDENTE DE VEHÍCULO AUTOMOTOR CON FALLECIDO | D31: 0
... B301: 70108 | C301: OTRAS LLAMADAS DE NO EMERGENCIA | D301: 35
B302: Total | D302: =SUM(D20:D301) -> 314

Sheet C016
B6: SECRETARIA DE SEGURIDAD Y PROTECCIÓN CIUDADANA
B7: SECRETARIADO EJECUTIVO DEL SISTEMA NACIONAL DE SEGURIDAD PUBLICA
B8: CENTRO NACIONAL DE INFORMACIÓN
B10: (FORMATO ELECTRÓNICO FESE V.2.0)
C12: Nombre de la Entidad Federativa: | D12: =RESUMEN!C10 -> Guanajuato
C13: Año: | D13: =RESUMEN!C11 -> 2026
C14: Mes: | D14: =RESUMEN!C12 -> Julio
B16: CENTRO DE ATENCIÓN DE LLAMADAS DE EMERGENCIAS
B17: Tipo de Administración: | D17: Municipal
B18: Nombre del Centro: | D18: Irapuato
B19: ID | C19: Incidente | D19: Cantidad
B20: 10101 | C20: ACCIDENTE ACUÁTICO CON LESIONADOS | D20: 0
B21: 10102 | C21: ACCIDENTE DE AERONAVE CON LESIONADOS | D21: 0
B22: 10103 | C22: ACCIDENTE DE MOTOCICLETA CON LESIONADOS | D22: 116
B23: 10104 | C23: ACCIDENTE DE VEHÍCULO AUTOMOTOR CON LESIONADOS | D23: 0
B24: 10105 | C24: ACCIDENTE FERROVIARIO CON LESIONADOS | D24: 0
B25: 10106 | C25: ACCIDENTE FERROVIARIO CON FALLECIDO | D25: 0
B26: 10107 | C26: ACCIDENTE MÚLTIPLE CON LESIONADOS | D26: 586
B27: 10108 | C27: ACCIDENTE MÚLTIPLE CON FALLECIDO | D27: 0
B28: 10109 | C28: ACCIDENTE DE VEHÍCULO DE PASAJEROS CON LESIONADOS | D28: 0
B29: 10110 | C29: ACCIDENTE DE VEHÍCULO DE PASAJEROS CON FALLECIDO | D29: 0
B30: 10111 | C30: ACCIDENTE DE MOTOCICLETA CON FALLECIDO | D30: 1
B31: 10112 | C31: ACCIDENTE DE VEHÍCULO AUTOMOTOR CON FALLECIDO | D31: 0
... B301: 70108 | C301: OTRAS LLAMADAS DE NO EMERGENCIA | D301: 2079
B302: Total | D302: =SUM(D20:D301) -> 36994

Sheet C017
B6: SECRETARIA DE SEGURIDAD Y PROTECCIÓN CIUDADANA
B7: SECRETARIADO EJECUTIVO DEL SISTEMA NACIONAL DE SEGURIDAD PUBLICA
B8: CENTRO NACIONAL DE INFORMACIÓN
B10: (FORMATO ELECTRÓNICO FESE V.2.0)
C12: Nombre de la Entidad Federativa: | D12: =RESUMEN!C10 -> Guanajuato
C13: Año: | D13: =RESUMEN!C11 -> 2026
C14: Mes: | D14: =RESUMEN!C12 -> Julio
B16: CENTRO DE ATENCIÓN DE LLAMADAS DE EMERGENCIAS
B17: Tipo de Administración: | D17: Municipal
B18: Nombre del Centro: | D18: Jaral del progreso
B19: ID | C19: Incidente | D19: Cantidad
B20: 10101 | C20: ACCIDENTE ACUÁTICO CON LESIONADOS | D20: 0
B21: 10102 | C21: ACCIDENTE DE AERONAVE CON LESIONADOS | D21: 0
B22: 10103 | C22: ACCIDENTE DE MOTOCICLETA CON LESIONADOS | D22: 9
B23: 10104 | C23: ACCIDENTE DE VEHÍCULO AUTOMOTOR CON LESIONADOS | D23: 0
B24: 10105 | C24: ACCIDENTE FERROVIARIO CON LESIONADOS | D24: 0
B25: 10106 | C25: ACCIDENTE FERROVIARIO CON FALLECIDO | D25: 0
B26: 10107 | C26: ACCIDENTE MÚLTIPLE CON LESIONADOS | D26: 4
B27: 10108 | C27: ACCIDENTE MÚLTIPLE CON FALLECIDO | D27: 0
B28: 10109 | C28: ACCIDENTE DE VEHÍCULO DE PASAJEROS CON LESIONADOS | D28: 0
B29: 10110 | C29: ACCIDENTE DE VEHÍCULO DE PASAJEROS CON FALLECIDO | D29: 0
B30: 10111 | C30: ACCIDENTE DE MOTOCICLETA CON FALLECIDO | D30: 0
B31: 10112 | C31: ACCIDENTE DE VEHÍCULO AUTOMOTOR CON FALLECIDO | D31: 0
... B301: 70108 | C301: OTRAS LLAMADAS DE NO EMERGENCIA | D301: 497
B302: Total | D302: =SUM(D20:D301) -> 1330

Sheet C018
B6: SECRETARIA DE SEGURIDAD Y PROTECCIÓN CIUDADANA
B7: SECRETARIADO EJECUTIVO DEL SISTEMA NACIONAL DE SEGURIDAD PUBLICA
B8: CENTRO NACIONAL DE INFORMACIÓN
B10: (FORMATO ELECTRÓNICO FESE V.2.0)
C12: Nombre de la Entidad Federativa: | D12: =RESUMEN!C10 -> Guanajuato
C13: Año: | D13: =RESUMEN!C11 -> 2026
C14: Mes: | D14: =RESUMEN!C12 -> Julio
B16: CENTRO DE ATENCIÓN DE LLAMADAS DE EMERGENCIAS
B17: Tipo de Administración: | D17: Municipal
B18: Nombre del Centro: | D18: Jerécuaro
B19: ID | C19: Incidente | D19: Cantidad
B20: 10101 | C20: ACCIDENTE ACUÁTICO CON LESIONADOS | D20: 0
B21: 10102 | C21: ACCIDENTE DE AERONAVE CON LESIONADOS | D21: 0
B22: 10103 | C22: ACCIDENTE DE MOTOCICLETA CON LESIONADOS | D22: 3
B23: 10104 | C23: ACCIDENTE DE VEHÍCULO AUTOMOTOR CON LESIONADOS | D23: 0
B24: 10105 | C24: ACCIDENTE FERROVIARIO CON LESIONADOS | D24: 0
B25: 10106 | C25: ACCIDENTE FERROVIARIO CON FALLECIDO | D25: 0
B26: 10107 | C26: ACCIDENTE MÚLTIPLE CON LESIONADOS | D26: 8
B27: 10108 | C27: ACCIDENTE MÚLTIPLE CON FALLECIDO | D27: 0
B28: 10109 | C28: ACCIDENTE DE VEHÍCULO DE PASAJEROS CON LESIONADOS | D28: 0
B29: 10110 | C29: ACCIDENTE DE VEHÍCULO DE PASAJEROS CON FALLECIDO | D29: 0
B30: 10111 | C30: ACCIDENTE DE MOTOCICLETA CON FALLECIDO | D30: 0
B31: 10112 | C31: ACCIDENTE DE VEHÍCULO AUTOMOTOR CON FALLECIDO | D31: 0
... B301: 70108 | C301: OTRAS LLAMADAS DE NO EMERGENCIA | D301: 466
B302: Total | D302: =SUM(D20:D301) -> 2594

Sheet C019
B6: SECRETARIA DE SEGURIDAD Y PROTECCIÓN CIUDADANA
B7: SECRETARIADO EJECUTIVO DEL SISTEMA NACIONAL DE SEGURIDAD PUBLICA
B8: CENTRO NACIONAL DE INFORMACIÓN
B10: (FORMATO ELECTRÓNICO FESE V.2.0)
C12: Nombre de la Entidad Federativa: | D12: =RESUMEN!C10 -> Guanajuato
C13: Año: | D13: =RESUMEN!C11 -> 2026
C14: Mes: | D14: =RESUMEN!C12 -> Julio
B16: CENTRO DE ATENCIÓN DE LLAMADAS DE EMERGENCIAS
B17: Tipo de Administración: | D17: Municipal
B18: Nombre del Centro: | D18: Juventino Rosas
B19: ID | C19: Incidente | D19: Cantidad
B20: 10101 | C20: ACCIDENTE ACUÁTICO CON LESIONADOS | D20: 0
B21: 10102 | C21: ACCIDENTE DE AERONAVE CON LESIONADOS | D21: 0
B22: 10103 | C22: ACCIDENTE DE MOTOCICLETA CON LESIONADOS | D22: 15
B23: 10104 | C23: ACCIDENTE DE VEHÍCULO AUTOMOTOR CON LESIONADOS | D23: 0
B24: 10105 | C24: ACCIDENTE FERROVIARIO CON LESIONADOS | D24: 0
B25: 10106 | C25: ACCIDENTE FERROVIARIO CON FALLECIDO | D25: 0
B26: 10107 | C26: ACCIDENTE MÚLTIPLE CON LESIONADOS | D26: 11
B27: 10108 | C27: ACCIDENTE MÚLTIPLE CON FALLECIDO | D27: 0
B28: 10109 | C28: ACCIDENTE DE VEHÍCULO DE PASAJEROS CON LESIONADOS | D28: 0
B29: 10110 | C29: ACCIDENTE DE VEHÍCULO DE PASAJEROS CON FALLECIDO | D29: 0
B30: 10111 | C30: ACCIDENTE DE MOTOCICLETA CON FALLECIDO | D30: 0
B31: 10112 | C31: ACCIDENTE DE VEHÍCULO AUTOMOTOR CON FALLECIDO | D31: 0
... B301: 70108 | C301: OTRAS LLAMADAS DE NO EMERGENCIA | D301: 687
B302: Total | D302: =SUM(D20:D301) -> 3447

Sheet C020
B6: SECRETARIA DE SEGURIDAD Y PROTECCIÓN CIUDADANA
B7: SECRETARIADO EJECUTIVO DEL SISTEMA NACIONAL DE SEGURIDAD PUBLICA
B8: CENTRO NACIONAL DE INFORMACIÓN
B10: (FORMATO ELECTRÓNICO FESE V.2.0)
C12: Nombre de la Entidad Federativa: | D12: =RESUMEN!C10 -> Guanajuato
C13: Año: | D13: =RESUMEN!C11 -> 2026
C14: Mes: | D14: =RESUMEN!C12 -> Julio
B16: CENTRO DE ATENCIÓN DE LLAMADAS DE EMERGENCIAS
B17: Tipo de Administración: | D17: Municipal
B18: Nombre del Centro: | D18: León
B19: ID | C19: Incidente | D19: Cantidad
B20: 10101 | C20: ACCIDENTE ACUÁTICO CON LESIONADOS | D20: 0
B21: 10102 | C21: ACCIDENTE DE AERONAVE CON LESIONADOS | D21: 0
B22: 10103 | C22: ACCIDENTE DE MOTOCICLETA CON LESIONADOS | D22: 309
B23: 10104 | C23: ACCIDENTE DE VEHÍCULO AUTOMOTOR CON LESIONADOS | D23: 1
B24: 10105 | C24: ACCIDENTE FERROVIARIO CON LESIONADOS | D24: 0
B25: 10106 | C25: ACCIDENTE FERROVIARIO CON FALLECIDO | D25: 0
B26: 10107 | C26: ACCIDENTE MÚLTIPLE CON LESIONADOS | D26: 816
B27: 10108 | C27: ACCIDENTE MÚLTIPLE CON FALLECIDO | D27: 0
B28: 10109 | C28: ACCIDENTE DE VEHÍCULO DE PASAJEROS CON LESIONADOS | D28: 2
B29: 10110 | C29: ACCIDENTE DE VEHÍCULO DE PASAJEROS CON FALLECIDO | D29: 0
B30: 10111 | C30: ACCIDENTE DE MOTOCICLETA CON FALLECIDO | D30: 0
B31: 10112 | C31: ACCIDENTE DE VEHÍCULO AUTOMOTOR CON FALLECIDO | D31: 0
... B301: 70108 | C301: OTRAS LLAMADAS DE NO EMERGENCIA | D301: 21069
B302: Total | D302: =SUM(D20:D301) -> 96103

Sheet C021
B6: SECRETARIA DE SEGURIDAD Y PROTECCIÓN CIUDADANA
B7: SECRETARIADO EJECUTIVO DEL SISTEMA NACIONAL DE SEGURIDAD PUBLICA
B8: CENTRO NACIONAL DE INFORMACIÓN
B10: (FORMATO ELECTRÓNICO FESE V.2.0)
C12: Nombre de la Entidad Federativa: | D12: =RESUMEN!C10 -> Guanajuato
C13: Año: | D13: =RESUMEN!C11 -> 2026
C14: Mes: | D14: =RESUMEN!C12 -> Julio
B16: CENTRO DE ATENCIÓN DE LLAMADAS DE EMERGENCIAS
B17: Tipo de Administración: | D17: Municipal
B18: Nombre del Centro: | D18: Moroleon
B19: ID | C19: Incidente | D19: Cantidad
B20: 10101 | C20: ACCIDENTE ACUÁTICO CON LESIONADOS | D20: 0
B21: 10102 | C21: ACCIDENTE DE AERONAVE CON LESIONADOS | D21: 0
B22: 10103 | C22: ACCIDENTE DE MOTOCICLETA CON LESIONADOS | D22: 27
B23: 10104 | C23: ACCIDENTE DE VEHÍCULO AUTOMOTOR CON LESIONADOS | D23: 0
B24: 10105 | C24: ACCIDENTE FERROVIARIO CON LESIONADOS | D24: 0
B25: 10106 | C25: ACCIDENTE FERROVIARIO CON FALLECIDO | D25: 0
B26: 10107 | C26: ACCIDENTE MÚLTIPLE CON LESIONADOS | D26: 52
B27: 10108 | C27: ACCIDENTE MÚLTIPLE CON FALLECIDO | D27: 0
B28: 10109 | C28: ACCIDENTE DE VEHÍCULO DE PASAJEROS CON LESIONADOS | D28: 0
B29: 10110 | C29: ACCIDENTE DE VEHÍCULO DE PASAJEROS CON FALLECIDO | D29: 0
B30: 10111 | C30: ACCIDENTE DE MOTOCICLETA CON FALLECIDO | D30: 0
B31: 10112 | C31: ACCIDENTE DE VEHÍCULO AUTOMOTOR CON FALLECIDO | D31: 0
... B301: 70108 | C301: OTRAS LLAMADAS DE NO EMERGENCIA | D301: 1332
B302: Total | D302: =SUM(D20:D301) -> 3222

Sheet C022
B6: SECRETARIA DE SEGURIDAD Y PROTECCIÓN CIUDADANA
B7: SECRETARIADO EJECUTIVO DEL SISTEMA NACIONAL DE SEGURIDAD PUBLICA
B8: CENTRO NACIONAL DE INFORMACIÓN
B10: (FORMATO ELECTRÓNICO FESE V.2.0)
C12: Nombre de la Entidad Federativa: | D12: =RESUMEN!C10 -> Guanajuato
C13: Año: | D13: =RESUMEN!C11 -> 2026
C14: Mes: | D14: =RESUMEN!C12 -> Julio
B16: CENTRO DE ATENCIÓN DE LLAMADAS DE EMERGENCIAS
B17: Tipo de Administración: | D17: Municipal
B18: Nombre del Centro: | D18: Ocampo
B19: ID | C19: Incidente | D19: Cantidad
B20: 10101 | C20: ACCIDENTE ACUÁTICO CON LESIONADOS | D20: 0
B21: 10102 | C21: ACCIDENTE DE AERONAVE CON LESIONADOS | D21: 0
B22: 10103 | C22: ACCIDENTE DE MOTOCICLETA CON LESIONADOS | D22: 11
B23: 10104 | C23: ACCIDENTE DE VEHÍCULO AUTOMOTOR CON LESIONADOS | D23: 0
B24: 10105 | C24: ACCIDENTE FERROVIARIO CON LESIONADOS | D24: 0
B25: 10106 | C25: ACCIDENTE FERROVIARIO CON FALLECIDO | D25: 0
B26: 10107 | C26: ACCIDENTE MÚLTIPLE CON LESIONADOS | D26: 4
B27: 10108 | C27: ACCIDENTE MÚLTIPLE CON FALLECIDO | D27: 0
B28: 10109 | C28: ACCIDENTE DE VEHÍCULO DE PASAJEROS CON LESIONADOS | D28: 0
B29: 10110 | C29: ACCIDENTE DE VEHÍCULO DE PASAJEROS CON FALLECIDO | D29: 0
B30: 10111 | C30: ACCIDENTE DE MOTOCICLETA CON FALLECIDO | D30: 0
B31: 10112 | C31: ACCIDENTE DE VEHÍCULO AUTOMOTOR CON FALLECIDO | D31: 0
... B301: 70108 | C301: OTRAS LLAMADAS DE NO EMERGENCIA | D301: 397
B302: Total | D302: =SUM(D20:D301) -> 1220

Sheet C023
B6: SECRETARIA DE SEGURIDAD Y PROTECCIÓN CIUDADANA
B7: SECRETARIADO EJECUTIVO DEL SISTEMA NACIONAL DE SEGURIDAD PUBLICA
B8: CENTRO NACIONAL DE INFORMACIÓN
B10: (FORMATO ELECTRÓNICO FESE V.2.0)
C12: Nombre de la Entidad Federativa: | D12: =RESUMEN!C10 -> Guanajuato
C13: Año: | D13: =RESUMEN!C11 -> 2026
C14: Mes: | D14: =RESUMEN!C12 -> Julio
B16: CENTRO DE ATENCIÓN DE LLAMADAS DE EMERGENCIAS
B17: Tipo de Administración: | D17: Municipal
B18: Nombre del Centro: | D18: Penjamo
B19: ID | C19: Incidente | D19: Cantidad
B20: 10101 | C20: ACCIDENTE ACUÁTICO CON LESIONADOS | D20: 0
B21: 10102 | C21: ACCIDENTE DE AERONAVE CON LESIONADOS | D21: 0
B22: 10103 | C22: ACCIDENTE DE MOTOCICLETA CON LESIONADOS | D22: 44
B23: 10104 | C23: ACCIDENTE DE VEHÍCULO AUTOMOTOR CON LESIONADOS | D23: 0
B24: 10105 | C24: ACCIDENTE FERROVIARIO CON LESIONADOS | D24: 0
B25: 10106 | C25: ACCIDENTE FERROVIARIO CON FALLECIDO | D25: 0
B26: 10107 | C26: ACCIDENTE MÚLTIPLE CON LESIONADOS | D26: 13
B27: 10108 | C27: ACCIDENTE MÚLTIPLE CON FALLECIDO | D27: 0
B28: 10109 | C28: ACCIDENTE DE VEHÍCULO DE PASAJEROS CON LESIONADOS | D28: 0
B29: 10110 | C29: ACCIDENTE DE VEHÍCULO DE PASAJEROS CON FALLECIDO | D29: 0
B30: 10111 | C30: ACCIDENTE DE MOTOCICLETA CON FALLECIDO | D30: 0
B31: 10112 | C31: ACCIDENTE DE VEHÍCULO AUTOMOTOR CON FALLECIDO | D31: 0
... B301: 70108 | C301: OTRAS LLAMADAS DE NO EMERGENCIA | D301: 1462
B302: Total | D302: =SUM(D20:D301) -> 6201

Sheet C024
B6: SECRETARIA DE SEGURIDAD Y PROTECCIÓN CIUDADANA
B7: SECRETARIADO EJECUTIVO DEL SISTEMA NACIONAL DE SEGURIDAD PUBLICA
B8: CENTRO NACIONAL DE INFORMACIÓN
B10: (FORMATO ELECTRÓNICO FESE V.2.0)
C12: Nombre de la Entidad Federativa: | D12: =RESUMEN!C10 -> Guanajuato
C13: Año: | D13: =RESUMEN!C11 -> 2026
C14: Mes: | D14: =RESUMEN!C12 -> Julio
B16: CENTRO DE ATENCIÓN DE LLAMADAS DE EMERGENCIAS
B17: Tipo de Administración: | D17: Municipal
B18: Nombre del Centro: | D18: Pueblo Nuevo
B19: ID | C19: Incidente | D19: Cantidad
B20: 10101 | C20: ACCIDENTE ACUÁTICO CON LESIONADOS | D20: 0
B21: 10102 | C21: ACCIDENTE DE AERONAVE CON LESIONADOS | D21: 0
B22: 10103 | C22: ACCIDENTE DE MOTOCICLETA CON LESIONADOS | D22: 0
B23: 10104 | C23: ACCIDENTE DE VEHÍCULO AUTOMOTOR CON LESIONADOS | D23: 1
B24: 10105 | C24: ACCIDENTE FERROVIARIO CON LESIONADOS | D24: 0
B25: 10106 | C25: ACCIDENTE FERROVIARIO CON FALLECIDO | D25: 0
B26: 10107 | C26: ACCIDENTE MÚLTIPLE CON LESIONADOS | D26: 0
B27: 10108 | C27: ACCIDENTE MÚLTIPLE CON FALLECIDO | D27: 0
B28: 10109 | C28: ACCIDENTE DE VEHÍCULO DE PASAJEROS CON LESIONADOS | D28: 0
B29: 10110 | C29: ACCIDENTE DE VEHÍCULO DE PASAJEROS CON FALLECIDO | D29: 0
B30: 10111 | C30: ACCIDENTE DE MOTOCICLETA CON FALLECIDO | D30: 0
B31: 10112 | C31: ACCIDENTE DE VEHÍCULO AUTOMOTOR CON FALLECIDO | D31: 0
... B301: 70108 | C301: OTRAS LLAMADAS DE NO EMERGENCIA | D301: 76
B302: Total | D302: =SUM(D20:D301) -> 105

Sheet C025
B6: SECRETARIA DE SEGURIDAD Y PROTECCIÓN CIUDADANA
B7: SECRETARIADO EJECUTIVO DEL SISTEMA NACIONAL DE SEGURIDAD PUBLICA
B8: CENTRO NACIONAL DE INFORMACIÓN
B10: (FORMATO ELECTRÓNICO FESE V.2.0)
C12: Nombre de la Entidad Federativa: | D12: =RESUMEN!C10 -> Guanajuato
C13: Año: | D13: =RESUMEN!C11 -> 2026
C14: Mes: | D14: =RESUMEN!C12 -> Julio
B16: CENTRO DE ATENCIÓN DE LLAMADAS DE EMERGENCIAS
B17: Tipo de Administración: | D17: Municipal
B18: Nombre del Centro: | D18: Romita
B19: ID | C19: Incidente | D19: Cantidad
B20: 10101 | C20: ACCIDENTE ACUÁTICO CON LESIONADOS | D20: 0
B21: 10102 | C21: ACCIDENTE DE AERONAVE CON LESIONADOS | D21: 0
B22: 10103 | C22: ACCIDENTE DE MOTOCICLETA CON LESIONADOS | D22: 6
B23: 10104 | C23: ACCIDENTE DE VEHÍCULO AUTOMOTOR CON LESIONADOS | D23: 0
B24: 10105 | C24: ACCIDENTE FERROVIARIO CON LESIONADOS | D24: 0
B25: 10106 | C25: ACCIDENTE FERROVIARIO CON FALLECIDO | D25: 0
B26: 10107 | C26: ACCIDENTE MÚLTIPLE CON LESIONADOS | D26: 6
B27: 10108 | C27: ACCIDENTE MÚLTIPLE CON FALLECIDO | D27: 0
B28: 10109 | C28: ACCIDENTE DE VEHÍCULO DE PASAJEROS CON LESIONADOS | D28: 0
B29: 10110 | C29: ACCIDENTE DE VEHÍCULO DE PASAJEROS CON FALLECIDO | D29: 0
B30: 10111 | C30: ACCIDENTE DE MOTOCICLETA CON FALLECIDO | D30: 0
B31: 10112 | C31: ACCIDENTE DE VEHÍCULO AUTOMOTOR CON FALLECIDO | D31: 0
... B301: 70108 | C301: OTRAS LLAMADAS DE NO EMERGENCIA | D301: 238
B302: Total | D302: =SUM(D20:D301) -> 3024

Sheet C026
B6: SECRETARIA DE SEGURIDAD Y PROTECCIÓN CIUDADANA
B7: SECRETARIADO EJECUTIVO DEL SISTEMA NACIONAL DE SEGURIDAD PUBLICA
B8: CENTRO NACIONAL DE INFORMACIÓN
B10: (FORMATO ELECTRÓNICO FESE V.2.0)
C12: Nombre de la Entidad Federativa: | D12: =RESUMEN!C10 -> Guanajuato
C13: Año: | D13: =RESUMEN!C11 -> 2026
C14: Mes: | D14: =RESUMEN!C12 -> Julio
B16: CENTRO DE ATENCIÓN DE LLAMADAS DE EMERGENCIAS
B17: Tipo de Administración: | D17: Municipal
B18: Nombre del Centro: | D18: Salamanca
B19: ID | C19: Incidente | D19: Cantidad
B20: 10101 | C20: ACCIDENTE ACUÁTICO CON LESIONADOS | D20: 0
B21: 10102 | C21: ACCIDENTE DE AERONAVE CON LESIONADOS | D21: 0
B22: 10103 | C22: ACCIDENTE DE MOTOCICLETA CON LESIONADOS | D22: 68
B23: 10104 | C23: ACCIDENTE DE VEHÍCULO AUTOMOTOR CON LESIONADOS | D23: 2
B24: 10105 | C24: ACCIDENTE FERROVIARIO CON LESIONADOS | D24: 0
B25: 10106 | C25: ACCIDENTE FERROVIARIO CON FALLECIDO | D25: 0
B26: 10107 | C26: ACCIDENTE MÚLTIPLE CON LESIONADOS | D26: 172
B27: 10108 | C27: ACCIDENTE MÚLTIPLE CON FALLECIDO | D27: 0
B28: 10109 | C28: ACCIDENTE DE VEHÍCULO DE PASAJEROS CON LESIONADOS | D28: 0
B29: 10110 | C29: ACCIDENTE DE VEHÍCULO DE PASAJEROS CON FALLECIDO | D29: 0
B30: 10111 | C30: ACCIDENTE DE MOTOCICLETA CON FALLECIDO | D30: 0
B31: 10112 | C31: ACCIDENTE DE VEHÍCULO AUTOMOTOR CON FALLECIDO | D31: 0
... B301: 70108 | C301: OTRAS LLAMADAS DE NO EMERGENCIA | D301: 2215
B302: Total | D302: =SUM(D20:D301) -> 11642

Sheet C027
B6: SECRETARIA DE SEGURIDAD Y PROTECCIÓN CIUDADANA
B7: SECRETARIADO EJECUTIVO DEL SISTEMA NACIONAL DE SEGURIDAD PUBLICA
B8: CENTRO NACIONAL DE INFORMACIÓN
B10: (FORMATO ELECTRÓNICO FESE V.2.0)
C12: Nombre de la Entidad Federativa: | D12: =RESUMEN!C10 -> Guanajuato
C13: Año: | D13: =RESUMEN!C11 -> 2026
C14: Mes: | D14: =RESUMEN!C12 -> Julio
B16: CENTRO DE ATENCIÓN DE LLAMADAS DE EMERGENCIAS
B17: Tipo de Administración: | D17: Municipal
B18: Nombre del Centro: | D18: Salvatierra
B19: ID | C19: Incidente | D19: Cantidad
B20: 10101 | C20: ACCIDENTE ACUÁTICO CON LESIONADOS | D20: 0
B21: 10102 | C21: ACCIDENTE DE AERONAVE CON LESIONADOS | D21: 0
B22: 10103 | C22: ACCIDENTE DE MOTOCICLETA CON LESIONADOS | D22: 22
B23: 10104 | C23: ACCIDENTE DE VEHÍCULO AUTOMOTOR CON LESIONADOS | D23: 0
B24: 10105 | C24: ACCIDENTE FERROVIARIO CON LESIONADOS | D24: 0
B25: 10106 | C25: ACCIDENTE FERROVIARIO CON FALLECIDO | D25: 1
B26: 10107 | C26: ACCIDENTE MÚLTIPLE CON LESIONADOS | D26: 2
B27: 10108 | C27: ACCIDENTE MÚLTIPLE CON FALLECIDO | D27: 0
B28: 10109 | C28: ACCIDENTE DE VEHÍCULO DE PASAJEROS CON LESIONADOS | D28: 0
B29: 10110 | C29: ACCIDENTE DE VEHÍCULO DE PASAJEROS CON FALLECIDO | D29: 0
B30: 10111 | C30: ACCIDENTE DE MOTOCICLETA CON FALLECIDO | D30: 0
B31: 10112 | C31: ACCIDENTE DE VEHÍCULO AUTOMOTOR CON FALLECIDO | D31: 0
... B301: 70108 | C301: OTRAS LLAMADAS DE NO EMERGENCIA | D301: 1092
B302: Total | D302: =SUM(D20:D301) -> 4369

Sheet C028
B6: SECRETARIA DE SEGURIDAD Y PROTECCIÓN CIUDADANA
B7: SECRETARIADO EJECUTIVO DEL SISTEMA NACIONAL DE SEGURIDAD PUBLICA
B8: CENTRO NACIONAL DE INFORMACIÓN
B10: (FORMATO ELECTRÓNICO FESE V.2.0)
C12: Nombre de la Entidad Federativa: | D12: =RESUMEN!C10 -> Guanajuato
C13: Año: | D13: =RESUMEN!C11 -> 2026
C14: Mes: | D14: =RESUMEN!C12 -> Julio
B16: CENTRO DE ATENCIÓN DE LLAMADAS DE EMERGENCIAS
B17: Tipo de Administración: | D17: Municipal
B18: Nombre del Centro: | D18: San Diego de la Unión
B19: ID | C19: Incidente | D19: Cantidad
B20: 10101 | C20: ACCIDENTE ACUÁTICO CON LESIONADOS | D20: 0
B21: 10102 | C21: ACCIDENTE DE AERONAVE CON LESIONADOS | D21: 0
B22: 10103 | C22: ACCIDENTE DE MOTOCICLETA CON LESIONADOS | D22: 7
B23: 10104 | C23: ACCIDENTE DE VEHÍCULO AUTOMOTOR CON LESIONADOS | D23: 0
B24: 10105 | C24: ACCIDENTE FERROVIARIO CON LESIONADOS | D24: 0
B25: 10106 | C25: ACCIDENTE FERROVIARIO CON FALLECIDO | D25: 0
B26: 10107 | C26: ACCIDENTE MÚLTIPLE CON LESIONADOS | D26: 1
B27: 10108 | C27: ACCIDENTE MÚLTIPLE CON FALLECIDO | D27: 0
B28: 10109 | C28: ACCIDENTE DE VEHÍCULO DE PASAJEROS CON LESIONADOS | D28: 0
B29: 10110 | C29: ACCIDENTE DE VEHÍCULO DE PASAJEROS CON FALLECIDO | D29: 0
B30: 10111 | C30: ACCIDENTE DE MOTOCICLETA CON FALLECIDO | D30: 0
B31: 10112 | C31: ACCIDENTE DE VEHÍCULO AUTOMOTOR CON FALLECIDO | D31: 0
... B301: 70108 | C301: OTRAS LLAMADAS DE NO EMERGENCIA | D301: 230
B302: Total | D302: =SUM(D20:D301) -> 1465

Sheet C029
B6: SECRETARIA DE SEGURIDAD Y PROTECCIÓN CIUDADANA
B7: SECRETARIADO EJECUTIVO DEL SISTEMA NACIONAL DE SEGURIDAD PUBLICA
B8: CENTRO NACIONAL DE INFORMACIÓN
B10: (FORMATO ELECTRÓNICO FESE V.2.0)
C12: Nombre de la Entidad Federativa: | D12: =RESUMEN!C10 -> Guanajuato
C13: Año: | D13: =RESUMEN!C11 -> 2026
C14: Mes: | D14: =RESUMEN!C12 -> Julio
B16: CENTRO DE ATENCIÓN DE LLAMADAS DE EMERGENCIAS
B17: Tipo de Administración: | D17: Municipal
B18: Nombre del Centro: | D18: San Felipe
B19: ID | C19: Incidente | D19: Cantidad
B20: 10101 | C20: ACCIDENTE ACUÁTICO CON LESIONADOS | D20: 0
B21: 10102 | C21: ACCIDENTE DE AERONAVE CON LESIONADOS | D21: 0
B22: 10103 | C22: ACCIDENTE DE MOTOCICLETA CON LESIONADOS | D22: 24
B23: 10104 | C23: ACCIDENTE DE VEHÍCULO AUTOMOTOR CON LESIONADOS | D23: 0
B24: 10105 | C24: ACCIDENTE FERROVIARIO CON LESIONADOS | D24: 0
B25: 10106 | C25: ACCIDENTE FERROVIARIO CON FALLECIDO | D25: 0
B26: 10107 | C26: ACCIDENTE MÚLTIPLE CON LESIONADOS | D26: 3
B27: 10108 | C27: ACCIDENTE MÚLTIPLE CON FALLECIDO | D27: 0
B28: 10109 | C28: ACCIDENTE DE VEHÍCULO DE PASAJEROS CON LESIONADOS | D28: 0
B29: 10110 | C29: ACCIDENTE DE VEHÍCULO DE PASAJEROS CON FALLECIDO | D29: 0
